Workbook

Sheet Sheet1
A1: 1) Conditional formatting
B4: date | C4: raj | D4: rahul | E4: ramesh | F4: raju | H4: sorting..
B5: 45691 | C5: 5729 | D5: 7582 | E5: 8041 | F5: 157049 | G5: =sum($C5:$F5) -> 178401 | H5: 14582079
B6: 45825 | C6: 18420 | D6: 32019 | E6: 917205 | F6: 8032 | G6: =sum($C6:$F6) -> 975676 | H6: 18475029
B7: 45990 | C7: 93058 | D7: 482065 | E7: 35821 | F7: 941207 | G7: =sum($C7:$F7) -> 1552151 | H7: 19482037
B8: 45883 | C8: 624197 | D8: 9173 | E8: 429870 | F8: 63472 | G8: =sum($C8:$F8) -> 1126712 | H8: 26058391
B9: 45679 | C9: 8721 | D9: 256047 | E9: 5208 | F9: 728095 | G9: =sum($C9:$F9) -> 998071 | H9: 37192058
B10: 45725 | C10: 39015 | D10: 69014 | E10: 648301 | F10: 28590 | G10: =sum($C10:$F10) -> 784920 | H10: 51720468
B11: 46022 | C11: 756482 | D11: 4829 | E11: 90325 | F11: 8103 | G11: =sum($C11:$F11) -> 859739 | H11: 59301726
B12: 45843 | C12: 1459 | D12: 831057 | E12: 726419 | F12: 379146 | G12: =sum($C12:$F12) -> 1938081 | H12: 60928317
B13: 45926 | C13: 308724 | D13: 62384 | E13: 4520 | F13: 572890 | G13: =sum($C13:$F13) -> 948518 | H13: 63051824
B14: 45796 | C14: 69105 | D14: 912370 | E14: 185074 | F14: 14053 | G14: =sum($C14:$F14) -> 1180602 | H14: 64058913
B15: 45941 | C15: 2486 | D15: 14820 | E15: 9204 | F15: 607182 | G15: =sum($C15:$F15) -> 633692 | H15: 67284905
B16: 45754 | C16: 573014 | D16: 307518 | E16: 719682 | F16: 38490 | G16: =sum($C16:$F16) -> 1638704 | H16: 70249361
... B24: 45921 | C24: 823017 | D24: 6452 | E24: 4573 | F24: 4381 | G24: =sum($C24:$F24) -> 838423 | H24: 91520478
B27: Bad | C27: red
B28: good | C28: yellow
B29: excellent | C29: green
A31: 2)Sorting and filter
B33: user id | C33: Player name
B34: 72839015 | C34: =VLOOKUP($B34,Sheet2!$B3:$C23,2,0) -> Aarav | D34: //vlookup
B35: 18475029 | C35: =VLOOKUP($B35,Sheet2!$B4:$C24,2,0) -> Ishita
B36: 90562137 | C36: =VLOOKUP($B36,Sheet2!$B5:$C25,2,0) -> Rohan
B37: 67284905 | C37: =VLOOKUP($B37,Sheet2!$B6:$C26,2,0) -> Meera
B38: 59301726 | C38: =VLOOKUP($B38,Sheet2!$B7:$C27,2,0) -> Aditya
B39: 82046193 | C39: =VLOOKUP($B39,Sheet2!$B8:$C28,2,0) -> Saanvi
B40: 37192058 | C40: =VLOOKUP($B40,Sheet2!$B9:$C29,2,0) -> Kabir
B41: 64058913 | C41: =VLOOKUP($B41,Sheet2!$B10:$C30,2,0) -> Anaya
B42: 51720468 | C42: =VLOOKUP($B42,Sheet2!$B11:$C31,2,0) -> Vivaan
B43: 73618204 | C43: =VLOOKUP($B43,Sheet2!$B12:$C32,2,0) -> Diya
B44: 89274016 | C44: =VLOOKUP($B44,Sheet2!$B13:$C33,2,0) -> Aryan
B45: 26058391 | C45: =VLOOKUP($B45,Sheet2!$B14:$C34,2,0) -> Riya
B46: 73045918 | C46: =VLOOKUP($B46,Sheet2!$B15:$C35,2,0) -> Kunal
... B53: 91520478 | C53: =VLOOKUP($B53,Sheet2!$B22:$C42,2,0) -> Priya
A55: 3)data alignment
E56: //overflow
B57: date | C57: user id | D57: player name | E57: email | F57: surnames
B58: 45691 | C58: 72839015 | D58: Aarav | E58: https://example.com/profile/aarav | F58: Sharma
B59: 45825 | C59: 18475029 | D59: Ishita | E59: https://example.com/profile/ishita | F59: Verma
B60: 45990 | C60: 90562137 | D60: Rohan | E60: https://example.com/profile/rohan | F60: Patel
...

Sheet Sheet3
A1: imported date from sheet 1 (A150:C201)
A3: =IFERROR(__xludf.DUMMYFUNCTION("IMPORTRANGE(""1xTpFXesw_M3wrx-tkV6V3zageVpt--qdKjmAtLU6Jq8"",""sheet1!A150:C201"")"),"Name") -> Name | B3: =IFERROR(__xludf.DUMMYFUNCTION("""COMPUTED_VALUE"""),"Age") -> Age | C3: =IFERROR(__xludf.DUMMYFUNCTION("""COMPUTED_VALUE"""),"Phone Number") -> Phone Number
A4: =IFERROR(__xludf.DUMMYFUNCTION("""COMPUTED_VALUE"""),"Aarav") -> Aarav | B4: =IFERROR(__xludf.DUMMYFUNCTION("""COMPUTED_VALUE"""),24.0) -> 24 | C4: =IFERROR(__xludf.DUMMYFUNCTION("""COMPUTED_VALUE"""),9.87654321E9) -> 9876543210
A5: =IFERROR(__xludf.DUMMYFUNCTION("""COMPUTED_VALUE"""),"Riya") -> Riya | B5: =IFERROR(__xludf.DUMMYFUNCTION("""COMPUTED_VALUE"""),28.0) -> 28 | C5: =IFERROR(__xludf.DUMMYFUNCTION("""COMPUTED_VALUE"""),9.12345678E9) -> 9123456780
A6: =IFERROR(__xludf.DUMMYFUNCTION("""COMPUTED_VALUE"""),"Kabir") -> Kabir | B6: =IFERROR(__xludf.DUMMYFUNCTION("""COMPUTED_VALUE"""),26.0) -> 26 | C6: =IFERROR(__xludf.DUMMYFUNCTION("""COMPUTED_VALUE"""),9.81234567E9) -> 9812345670
A7: =IFERROR(__xludf.DUMMYFUNCTION("""COMPUTED_VALUE"""),"Meera") -> Meera | B7: =IFERROR(__xludf.DUMMYFUNCTION("""COMPUTED_VALUE"""),22.0) -> 22 | C7: =IFERROR(__xludf.DUMMYFUNCTION("""COMPUTED_VALUE"""),9.898989898E9) -> 9898989898
A8: =IFERROR(__xludf.DUMMYFUNCTION("""COMPUTED_VALUE"""),"Aryan") -> Aryan | B8: =IFERROR(__xludf.DUMMYFUNCTION("""COMPUTED_VALUE"""),30.0) -> 30 | C8: =IFERROR(__xludf.DUMMYFUNCTION("""COMPUTED_VALUE"""),9.000000001E9) -> 9000000001
A9: =IFERROR(__xludf.DUMMYFUNCTION("""COMPUTED_VALUE"""),"Neha") -> Neha | B9: =IFERROR(__xludf.DUMMYFUNCTION("""COMPUTED_VALUE"""),24.0) -> 24 | C9: =IFERROR(__xludf.DUMMYFUNCTION("""COMPUTED_VALUE"""),9.87654321E9) -> 9876543210
A10: =IFERROR(__xludf.DUMMYFUNCTION("""COMPUTED_VALUE"""),"Kunal") -> Kunal | B10: =IFERROR(__xludf.DUMMYFUNCTION("""COMPUTED_VALUE"""),27.0) -> 27 | C10: =IFERROR(__xludf.DUMMYFUNCTION("""COMPUTED_VALUE"""),9.12345678E9) -> 9123456780
A11: =IFERROR(__xludf.DUMMYFUNCTION("""COMPUTED_VALUE"""),"Aarav") -> Aarav | B11: =IFERROR(__xludf.DUMMYFUNCTION("""COMPUTED_VALUE"""),24.0) -> 24 | C11: =IFERROR(__xludf.DUMMYFUNCTION("""COMPUTED_VALUE"""),9.87654321E9) -> 9876543210
A12: =IFERROR(__xludf.DUMMYFUNCTION("""COMPUTED_VALUE"""),"Priya") -> Priya | B12: =IFERROR(__xludf.DUMMYFUNCTION("""COMPUTED_VALUE"""),25.0) -> 25 | C12: =IFERROR(__xludf.DUMMYFUNCTION("""COMPUTED_VALUE"""),9.81234567E9) -> 9812345670
A13: =IFERROR(__xludf.DUMMYFUNCTION("""COMPUTED_VALUE"""),"Diya") -> Diya | B13: =IFERROR(__xludf.DUMMYFUNCTION("""COMPUTED_VALUE"""),23.0) -> 23 | C13: =IFERROR(__xludf.DUMMYFUNCTION("""COMPUTED_VALUE"""),9.898989898E9) -> 9898989898
A14: =IFERROR(__xludf.DUMMYFUNCTION("""COMPUTED_VALUE"""),"Raj") -> Raj | B14: =IFERROR(__xludf.DUMMYFUNCTION("""COMPUTED_VALUE"""),31.0) -> 31 | C14: =IFERROR(__xludf.DUMMYFUNCTION("""COMPUTED_VALUE"""),9.000000002E9) -> 9000000002
A15: =IFERROR(__xludf.DUMMYFUNCTION("""COMPUTED_VALUE"""),"Yash") -> Yash | B15: =IFERROR(__xludf.DUMMYFUNCTION("""COMPUTED_VALUE"""),28.0) -> 28 | C15: =IFERROR(__xludf.DUMMYFUNCTION("""COMPUTED_VALUE"""),9.12345678E9) -> 9123456780
A16: =IFERROR(__xludf.DUMMYFUNCTION("""COMPUTED_VALUE"""),"Anaya") -> Anaya | B16: =IFERROR(__xludf.DUMMYFUNCTION("""COMPUTED_VALUE"""),24.0) -> 24 | C16: =IFERROR(__xludf.DUMMYFUNCTION("""COMPUTED_VALUE"""),9.87654321E9) -> 9876543210
A17: =IFERROR(__xludf.DUMMYFUNCTION("""COMPUTED_VALUE"""),"Aarav") -> Aarav | B17: =IFERROR(__xludf.DUMMYFUNCTION("""COMPUTED_VALUE"""),24.0) -> 24 | C17: =IFERROR(__xludf.DUMMYFUNCTION("""COMPUTED_VALUE"""),9.87654321E9) -> 9876543210
A18: =IFERROR(__xludf.DUMMYFUNCTION("""COMPUTED_VALUE"""),"Riya") -> Riya | B18: =IFERROR(__xludf.DUMMYFUNCTION("""COMPUTED_VALUE"""),28.0) -> 28 | C18: =IFERROR(__xludf.DUMMYFUNCTION("""COMPUTED_VALUE"""),9.12345678E9) -> 9123456780
A19: =IFERROR(__xludf.DUMMYFUNCTION("""COMPUTED_VALUE"""),"Aryan") -> Aryan | B19: =IFERROR(__xludf.DUMMYFUNCTION("""COMPUTED_VALUE"""),30.0) -> 30 | C19: =IFERROR(__xludf.DUMMYFUNCTION("""COMPUTED_VALUE"""),9.000000001E9) -> 9000000001
A20: =IFERROR(__xludf.DUMMYFUNCTION("""COMPUTED_VALUE"""),"Meera") -> Meera | B20: =IFERROR(__xludf.DUMMYFUNCTION("""COMPUTED_VALUE"""),22.0) -> 22 | C20: =IFERROR(__xludf.DUMMYFUNCTION("""COMPUTED_VALUE"""),9.898989898E9) -> 9898989898
A21: =IFERROR(__xludf.DUMMYFUNCTION("""COMPUTED_VALUE"""),"Kabir") -> Kabir | B21: =IFERROR(__xludf.DUMMYFUNCTION("""COMPUTED_VALUE"""),26.0) -> 26 | C21: =IFERROR(__xludf.DUMMYFUNCTION("""COMPUTED_VALUE"""),9.81234567E9) -> 9812345670
A22: =IFERROR(__xludf.DUMMYFUNCTION("""COMPUTED_VALUE"""),"Kunal") -> Kunal | B22: =IFERROR(__xludf.DUMMYFUNCTION("""COMPUTED_VALUE"""),27.0) -> 27 | C22: =IFERROR(__xludf.DUMMYFUNCTION("""COMPUTED_VALUE"""),9.12345678E9) -> 9123456780
A23: =IFERROR(__xludf.DUMMYFUNCTION("""COMPUTED_VALUE"""),"Diya") -> Diya | B23: =IFERROR(__xludf.DUMMYFUNCTION("""COMPUTED_VALUE"""),23.0) -> 23 | C23: =IFERROR(__xludf.DUMMYFUNCTION("""COMPUTED_VALUE"""),9.898989898E9) -> 9898989898
A24: =IFERROR(__xludf.DUMMYFUNCTION("""COMPUTED_VALUE"""),"Neha") -> Neha | B24: =IFERROR(__xludf.DUMMYFUNCTION("""COMPUTED_VALUE"""),24.0) -> 24 | C24: =IFERROR(__xludf.DUMMYFUNCTION("""COMPUTED_VALUE"""),9.87654321E9) -> 9876543210
A25: =IFERROR(__xludf.DUMMYFUNCTION("""COMPUTED_VALUE"""),"Vivaan") -> Vivaan | B25: =IFERROR(__xludf.DUMMYFUNCTION("""COMPUTED_VALUE"""),29.0) -> 29 | C25: =IFERROR(__xludf.DUMMYFUNCTION("""COMPUTED_VALUE"""),9.111111111E9) -> 9111111111
A26: =IFERROR(__xludf.DUMMYFUNCTION("""COMPUTED_VALUE"""),"Rohan") -> Rohan | B26: =IFERROR(__xludf.DUMMYFUNCTION("""COMPUTED_VALUE"""),26.0) -> 26 | C26: =IFERROR(__xludf.DUMMYFUNCTION("""COMPUTED_VALUE"""),9.81234567E9) -> 9812345670
A27: =IFERROR(__xludf.DUMMYFUNCTION("""COMPUTED_VALUE"""),"Simran") -> Simran | B27: =IFERROR(__xludf.DUMMYFUNCTION("""COMPUTED_VALUE"""),23.0) -> 23 | C27: =IFERROR(__xludf.DUMMYFUNCTION("""COMPUTED_VALUE"""),9.898989898E9) -> 9898989898
A28: =IFERROR(__xludf.DUMMYFUNCTION("""COMPUTED_VALUE"""),"Priya") -> Priya | B28: =IFERROR(__xludf.DUMMYFUNCTION("""COMPUTED_VALUE"""),25.0) -> 25 | C28: =IFERROR(__xludf.DUMMYFUNCTION("""COMPUTED_VALUE"""),9.81234567E9) -> 9812345670
A29: =IFERROR(__xludf.DUMMYFUNCTION("""COMPUTED_VALUE"""),"Aarav") -> Aarav | B29: =IFERROR(__xludf.DUMMYFUNCTION("""COMPUTED_VALUE"""),24.0) -> 24 | C29: =IFERROR(__xludf.DUMMYFUNCTION("""COMPUTED_VALUE"""),9.87654321E9) -> 9876543210
A30: =IFERROR(__xludf.DUMMYFUNCTION("""COMPUTED_VALUE"""),"Aryan") -> Aryan | B30: =IFERROR(__xludf.DUMMYFUNCTION("""COMPUTED_VALUE"""),30.0) -> 30 | C30: =IFERROR(__xludf.DUMMYFUNCTION("""COMPUTED_VALUE"""),9.000000001E9) -> 9000000001
A31: =IFERROR(__xludf.DUMMYFUNCTION("""COMPUTED_VALUE"""),"Anaya") -> Anaya | B31: =IFERROR(__xludf.DUMMYFUNCTION("""COMPUTED_VALUE"""),24.0) -> 24 | C31: =IFERROR(__xludf.DUMMYFUNCTION("""COMPUTED_VALUE"""),9.87654321E9) -> 9876543210
A32: =IFERROR(__xludf.DUMMYFUNCTION("""COMPUTED_VALUE"""),"Meera") -> Meera | B32: =IFERROR(__xludf.DUMMYFUNCTION("""COMPUTED_VALUE"""),22.0) -> 22 | C32: =IFERROR(__xludf.DUMMYFUNCTION("""COMPUTED_VALUE"""),9.898989898E9) -> 9898989898
A33: =IFERROR(__xludf.DUMMYFUNCTION("""COMPUTED_VALUE"""),"Raj") -> Raj | B33: =IFERROR(__xludf.DUMMYFUNCTION("""COMPUTED_VALUE"""),31.0) -> 31 | C33: =IFERROR(__xludf.DUMMYFUNCTION("""COMPUTED_VALUE"""),9.000000002E9) -> 9000000002
A34: =IFERROR(__xludf.DUMMYFUNCTION("""COMPUTED_VALUE"""),"Vivaan") -> Vivaan | B34: =IFERROR(__xludf.DUMMYFUNCTION("""COMPUTED_VALUE"""),29.0) -> 29 | C34: =IFERROR(__xludf.DUMMYFUNCTION("""COMPUTED_VALUE"""),9.111111111E9) -> 9111111111
A35: =IFERROR(__xludf.DUMMYFUNCTION("""COMPUTED_VALUE"""),"Riya") -> Riya | B35: =IFERROR(__xludf.DUMMYFUNCTION("""COMPUTED_VALUE"""),28.0) -> 28 | C35: =IFERROR(__xludf.DUMMYFUNCTION("""COMPUTED_VALUE"""),9.12345678E9) -> 9123456780
A36: =IFERROR(__xludf.DUMMYFUNCTION("""COMPUTED_VALUE"""),"Yash") -> Yash | B36: =IFERROR(__xludf.DUMMYFUNCTION("""COMPUTED_VALUE"""),28.0) -> 28 | C36: =IFERROR(__xludf.DUMMYFUNCTION("""COMPUTED_VALUE"""),9.12345678E9) -> 9123456780
A37: =IFERROR(__xludf.DUMMYFUNCTION("""COMPUTED_VALUE"""),"Priya") -> Priya | B37: =IFERROR(__xludf.DUMMYFUNCTION("""COMPUTED_VALUE"""),25.0) -> 25 | C37: =IFERROR(__xludf.DUMMYFUNCTION("""COMPUTED_VALUE"""),9.81234567E9) -> 9812345670
A38: =IFERROR(__xludf.DUMMYFUNCTION("""COMPUTED_VALUE"""),"Kunal") -> Kunal | B38: =IFERROR(__xludf.DUMMYFUNCTION("""COMPUTED_VALUE"""),27.0) -> 27 | C38: =IFERROR(__xludf.DUMMYFUNCTION("""COMPUTED_VALUE"""),9.12345678E9) -> 9123456780
A39: =IFERROR(__xludf.DUMMYFUNCTION("""COMPUTED_VALUE"""),"Neha") -> Neha | B39: =IFERROR(__xludf.DUMMYFUNCTION("""COMPUTED_VALUE"""),24.0) -> 24 | C39: =IFERROR(__xludf.DUMMYFUNCTION("""COMPUTED_VALUE"""),9.87654321E9) -> 9876543210
A40: =IFERROR(__xludf.DUMMYFUNCTION("""COMPUTED_VALUE"""),"Rohan") -> Rohan | B40: =IFERROR(__xludf.DUMMYFUNCTION("""COMPUTED_VALUE"""),26.0) -> 26 | C40: =IFERROR(__xludf.DUMMYFUNCTION("""COMPUTED_VALUE"""),9.81234567E9) -> 9812345670
A41: =IFERROR(__xludf.DUMMYFUNCTION("""COMPUTED_VALUE"""),"Kabir") -> Kabir | B41: =IFERROR(__xludf.DUMMYFUNCTION("""COMPUTED_VALUE"""),26.0) -> 26 | C41: =IFERROR(__xludf.DUMMYFUNCTION("""COMPUTED_VALUE"""),9.81234567E9) -> 9812345670
...

Sheet Sheet2
A3: date | B3: user id | C3: player name
A4: 45691 | B4: 72839015 | C4: Aarav
A5: 45825 | B5: 18475029 | C5: Ishita
A6: 45990 | B6: 90562137 | C6: Rohan
A7: 45883 | B7: 67284905 | C7: Meera
A8: 45679 | B8: 59301726 | C8: Aditya
A9: 45725 | B9: 82046193 | C9: Saanvi
A10: 46022 | B10: 37192058 | C10: Kabir
A11: 45843 | B11: 64058913 | C11: Anaya
A12: 45926 | B12: 51720468 | C12: Vivaan
A13: 45796 | B13: 73618204 | C13: Diya
A14: 45941 | B14: 89274016 | C14: Aryan
A15: 45754 | B15: 26058391 | C15: Riya
... A23: 45921 | B23: 91520478 | C23: Priya
